Workbook

Sheet bs2018.03
A1: 项目编号 | B1: 项目名称（元） | C1: 年初数 | D1: 期末数
A2: 40001 | B2: 货币资金
A3: 40002 | B3: 交易性金融资产
A4: 40003 | B4: 应收票据
A5: 40004 | B5: 应收账款
A6: 40005 | B6: 预付账款
A7: 40006 | B7: 存货
A8: 40007 | B8: 应收利息
A9: 40008 | B9: 应收股利
A10: 40009 | B10: 其他应收款
A11: 40010 | B11: 一年内到期的非流动资产
A12: 40011 | B12: 其他流动资产
A13: 40012 | B13: 流动资产合计 | C13: =SUM(C2:C12) -> 0 | D13: =SUM(D2:D12) -> 0
A14: 40013 | B14: 可供出售金融资产
A15: 40014 | B15: 持有至到期投资
A16: 40015 | B16: 长期应收款
A17: 40016 | B17: 长期股权投资
A18: 40017 | B18: 投资性房地产
A19: 400171 | B19: 固定资产
A20: 400172 | B20: 累计折旧
A21: 400173 | B21: 固定资产减值准备
A22: 40018 | B22: 固定资产净额 | C22: =C19-C20-C21 -> 0 | D22: =D19-D20-D21 -> 0
A23: 40019 | B23: 工程物资
A24: 40020 | B24: 在建工程
A25: 40021 | B25: 固定资产清理
A26: 40022 | B26: 生产性生物资产
A27: 40023 | B27: 油气资产
A28: 40024 | B28: 无形资产
A29: 40025 | B29: 开发支出
A30: 40026 | B30: 商誉
A31: 40027 | B31: 长期待摊费用
A32: 40028 | B32: 递延所得税资产
A33: 40029 | B33: 其他非流动资产
A34: 40030 | B34: 非流动资产合计 | C34: =SUM(C14:C33)-C19-C20-C21 -> 0 | D34: =SUM(D14:D33)-D19-D20-D21 -> 0
A35: 40031 | B35: 资产总计 | C35: =C34+C13 -> 0 | D35: =D34+D13 -> 0
A36: 40032 | B36: 短期借款
A37: 40033 | B37: 交易性金融负债
A38: 40034 | B38: 应付票据
A39: 40035 | B39: 应付账款
A40: 40036 | B40: 预收账款
...

Sheet pl2018.03
A1: 项目编号 | B1: 项目名称（元） | C1: 本月数 | D1: 本年累计
A2: 40064 | B2: 营业收入 | C2: =C3+C4 -> 0 | D2: =D3+D4 -> 0
A3: 400640 | B3: 主营业务收入
A4: 400641 | B4: 其他业务收入
A5: 40065 | B5: 营业成本 | C5: =C6+C7 -> 0 | D5: =D6+D7 -> 0
A6: 400650 | B6: 主营业务成本
A7: 400651 | B7: 其他业务成本
A8: 40066 | B8: 营业税金及附加
A9: 40067 | B9: 销售费用
A10: 40068 | B10: 管理费用
A11: 40069 | B11: 财务费用
A12: 40070 | B12: 资产减值损失
A13: 40071 | B13: 公允价值变动收益
A14: 40072 | B14: 投资收益
A15: 40073 | B15: 营业利润 | C15: =C2-C5-C8-C9-C10-C11-C12+C13+C14 -> 0 | D15: =D2-D5-D8-D9-D10-D11-D12+D13+D14 -> 0
A16: 40074 | B16: 营业外收入
A17: 40075 | B17: 营业外支出
A18: 40076 | B18: 利润总额 | C18: =C15+C16-C17 -> 0 | D18: =D15+D16-D17 -> 0
A19: 40077 | B19: 所得税费用
A20: 40078 | B20: 净利润 | C20: =C18-C19 -> 0 | D20: =D18-D19 -> 0
A21: 40079 | B21: 少数股东权益损益
A22: 40080 | B22: 归属于母公司所有者的净利润 | C22: =C20-C21 -> 0 | D22: =D20-D21 -> 0
A23: 40081 | B23: 每股收益
A24: 40082 | B24: 基本每股收益
A25: 40083 | B25: 稀释每股收益
A26: 40084 | B26: 年初未分配利润
A27: 40085 | B27: 盈余公积补亏
A28: 40086 | B28: 其他转入
A29: 40087 | B29: 可供分配利润
A30: 40088 | B30: 提取法定盈余公积
A31: 40089 | B31: 提取一般风险准备
A32: 40090 | B32: 其他
A33: 40091 | B33: 可供投资者分配的利润 | C33: =C22+C26+C32 -> 0 | D33: =D22+D26+D32 -> 0
A34: 40092 | B34: 应付优先股股利
A35: 40093 | B35: 提取任意盈余公积
A36: 40094 | B36: 应付普通股股利
A37: 40095 | B37: 转作股本的普通股股利
A38: 40096 | B38: 其他
A39: 40097 | B39: 未分配利润 | C39: =C33-C36 -> 0 | D39: =D33-D36-D38 -> 0
A40: 400831 | B40: 其他综合收益
...

Sheet cf2018.03
A1: 项目编号 | B1: 项目名称（元）
A2: 40098 | B2: 一、经营活动产生的现金流量：
A3: 40100 | B3: 销售商品、提供劳务收到的现金
A4: 40101 | B4: 收到的税费返还
A5: 40102 | B5: 收到其他与经营活动有关的现金
A6: 40103 | B6: 经营活动现金流入小计 | C6: =SUM(C3:C5) -> 0
A7: 40104 | B7: 购买商品、接受劳务支付的现金
A8: 40105 | B8: 支付给职工以及为职工支付的现金
A9: 40106 | B9: 支付的各项税费
A10: 40107 | B10: 支付的其他与经营活动有关的现金
A11: 40108 | B11: 经营活动现金流出小计 | C11: =SUM(C7:C10) -> 0
A12: 40109 | B12: 经营活动产生的现金流量净额 | C12: =C6-C11 -> 0
A13: 40110 | B13: 二、投资活动产生的现金流量：
A14: 40111 | B14: 收回投资所收到的现金
A15: 40112 | B15: 取得投资收益收到的现金
A16: 40113 | B16: 处置固定资产、无形资产和其他长期资产所收回的现金净额
A17: 40114 | B17: 处置子公司及其他营业单位收到的现金净额
A18: 40115 | B18: 收到的其他与投资活动有关的现金
A19: 40116 | B19: 投资活动现金流入小计 | C19: =SUM(C14:C18) -> 0
A20: 40117 | B20: 购建固定资产、无形资产和其他长期资产所支付的现金
A21: 40118 | B21: 投资支付的现金
A22: 40119 | B22: 取得子公司及其他营业单位支付的现金净额
A23: 40120 | B23: 支付其他与投资活动有关的现金
A24: 40121 | B24: 投资活动现金流出小计 | C24: =SUM(C20:C23) -> 0
A25: 40122 | B25: 投资活动产生的现金流量净额 | C25: =C19-C24 -> 0
A26: 40123 | B26: 三、筹资活动产生的现金流量：
A27: 40124 | B27: 吸收投资所收到的现金
A28: 40125 | B28: 取得借款所收到的现金
A29: 40126 | B29: 收到的其他与筹资活动有关的现金
A30: 40127 | B30: 筹资活动现金流入小计 | C30: =SUM(C27:C29) -> 0
A31: 40128 | B31: 偿还债务所支付的现金
A32: 40129 | B32: 分配股利、利润或偿付利息支付的现金
A33: 40130 | B33: 支付的其他与筹资活动有关的现金
A34: 40131 | B34: 筹资活动现金流出小计 | C34: =SUM(C31:C33) -> 0
A35: 40132 | B35: 筹资活动产生的现金流量净额 | C35: =C30-C34 -> 0
A36: 40133 | B36: 四、汇率变动对现金及现金等价物的影响
A37: 40134 | B37: 五、现金及现金等价物净增加额 | C37: =C12+C25+C35+C36 -> 0
A38: 40135 | B38: 期初现金及现金等价物余额
A39: 40136 | B39: 六、期末现金及现金等价物余额 | C39: =C37+C38 -> 0

Sheet bs2017.12
A1: 项目编号 | B1: 项目名称（元） | C1: 年初数 | D1: 期末数
A2: 40001 | B2: 货币资金
A3: 40002 | B3: 交易性金融资产
A4: 40003 | B4: 应收票据
A5: 40004 | B5: 应收账款
A6: 40005 | B6: 预付账款
A7: 40006 | B7: 存货
A8: 40007 | B8: 应收利息
A9: 40008 | B9: 应收股利
A10: 40009 | B10: 其他应收款
A11: 40010 | B11: 一年内到期的非流动资产
A12: 40011 | B12: 其他流动资产
A13: 40012 | B13: 流动资产合计 | C13: =SUM(C2:C12) -> 0 | D13: =SUM(D2:D12) -> 0
A14: 40013 | B14: 可供出售金融资产
A15: 40014 | B15: 持有至到期投资
A16: 40015 | B16: 长期应收款
A17: 40016 | B17: 长期股权投资
A18: 40017 | B18: 投资性房地产
A19: 400171 | B19: 固定资产
A20: 400172 | B20: 累计折旧
A21: 400173 | B21: 固定资产减值准备
A22: 40018 | B22: 固定资产净额 | C22: =C19-C20-C21 -> 0 | D22: =D19-D20-D21 -> 0
A23: 40019 | B23: 工程物资
A24: 40020 | B24: 在建工程
A25: 40021 | B25: 固定资产清理
A26: 40022 | B26: 生产性生物资产
A27: 40023 | B27: 油气资产
A28: 40024 | B28: 无形资产
A29: 40025 | B29: 开发支出
A30: 40026 | B30: 商誉
A31: 40027 | B31: 长期待摊费用
A32: 40028 | B32: 递延所得税资产
A33: 40029 | B33: 其他非流动资产
A34: 40030 | B34: 非流动资产合计 | C34: =SUM(C14:C33)-C19-C20-C21 -> 0 | D34: =SUM(D14:D33)-D19-D20-D21 -> 0
A35: 40031 | B35: 资产总计 | C35: =C34+C13 -> 0 | D35: =D34+D13 -> 0
A36: 40032 | B36: 短期借款
A37: 40033 | B37: 交易性金融负债
A38: 40034 | B38: 应付票据
A39: 40035 | B39: 应付账款
A40: 40036 | B40: 预收账款
...

Sheet pl2017.12
A1: 项目编号 | B1: 项目名称（元） | C1: 本月数
A2: 40064 | B2: 营业收入 | C2: =C3+C4 -> 0 | D2: =D3+D4 -> 0
A3: 400640 | B3: 主营业务收入
A4: 400641 | B4: 其他业务收入
A5: 40065 | B5: 营业成本 | C5: =C6+C7 -> 0 | D5: =D6+D7 -> 0
A6: 400650 | B6: 主营业务成本
A7: 400651 | B7: 其他业务成本
A8: 40066 | B8: 营业税金及附加
A9: 40067 | B9: 销售费用
A10: 40068 | B10: 管理费用
A11: 40069 | B11: 财务费用
A12: 40070 | B12: 资产减值损失
A13: 40071 | B13: 公允价值变动收益
A14: 40072 | B14: 投资收益
A15: 40073 | B15: 营业利润 | C15: =C2-C5-C8-C9-C10-C11-C12+C13+C14 -> 0 | D15: =D2-D5-D8-D9-D10-D11-D12+D13+D14 -> 0
A16: 40074 | B16: 营业外收入
A17: 40075 | B17: 营业外支出
A18: 40076 | B18: 利润总额 | C18: =C15+C16-C17 -> 0 | D18: =D15+D16-D17 -> 0
A19: 40077 | B19: 所得税费用
A20: 40078 | B20: 净利润 | C20: =C18-C19 -> 0 | D20: =D18-D19 -> 0
A21: 40079 | B21: 少数股东权益损益
A22: 40080 | B22: 归属于母公司所有者的净利润 | C22: =C20-C21 -> 0 | D22: =D20-D21 -> 0
A23: 40081 | B23: 每股收益
A24: 40082 | B24: 基本每股收益
A25: 40083 | B25: 稀释每股收益
A26: 40084 | B26: 年初未分配利润
A27: 40085 | B27: 盈余公积补亏
A28: 40086 | B28: 其他转入
A29: 40087 | B29: 可供分配利润
A30: 40088 | B30: 提取法定盈余公积
A31: 40089 | B31: 提取一般风险准备
A32: 40090 | B32: 其他
A33: 40091 | B33: 可供投资者分配的利润 | C33: =C22+C26+C32 -> 0 | D33: =D22+D26+D32 -> 0
A34: 40092 | B34: 应付优先股股利
A35: 40093 | B35: 提取任意盈余公积
A36: 40094 | B36: 应付普通股股利
A37: 40095 | B37: 转作股本的普通股股利
A38: 40096 | B38: 其他
A39: 40097 | B39: 未分配利润 | C39: =C33-C36 -> 0 | D39: =D33-D36 -> 0
A40: 400831 | B40: 其他综合收益
...

Sheet cf2017.12
A1: 项目编号 | B1: 项目名称（元）
A2: 40098 | B2: 一、经营活动产生的现金流量：
A3: 40100 | B3: 销售商品、提供劳务收到的现金
A4: 40101 | B4: 收到的税费返还
A5: 40102 | B5: 收到其他与经营活动有关的现金
A6: 40103 | B6: 经营活动现金流入小计 | C6: =SUM(C3:C5) -> 0
A7: 40104 | B7: 购买商品、接受劳务支付的现金
A8: 40105 | B8: 支付给职工以及为职工支付的现金
A9: 40106 | B9: 支付的各项税费
A10: 40107 | B10: 支付的其他与经营活动有关的现金
A11: 40108 | B11: 经营活动现金流出小计 | C11: =SUM(C7:C10) -> 0
A12: 40109 | B12: 经营活动产生的现金流量净额 | C12: =C6-C11 -> 0
A13: 40110 | B13: 二、投资活动产生的现金流量：
A14: 40111 | B14: 收回投资所收到的现金
A15: 40112 | B15: 取得投资收益收到的现金
A16: 40113 | B16: 处置固定资产、无形资产和其他长期资产所收回的现金净额
A17: 40114 | B17: 处置子公司及其他营业单位收到的现金净额
A18: 40115 | B18: 收到的其他与投资活动有关的现金
A19: 40116 | B19: 投资活动现金流入小计 | C19: =SUM(C14:C18) -> 0
A20: 40117 | B20: 购建固定资产、无形资产和其他长期资产所支付的现金
A21: 40118 | B21: 投资支付的现金
A22: 40119 | B22: 取得子公司及其他营业单位支付的现金净额
A23: 40120 | B23: 支付其他与投资活动有关的现金
A24: 40121 | B24: 投资活动现金流出小计 | C24: =SUM(C20:C23) -> 0
A25: 40122 | B25: 投资活动产生的现金流量净额 | C25: =C19-C24 -> 0
A26: 40123 | B26: 三、筹资活动产生的现金流量：
A27: 40124 | B27: 吸收投资所收到的现金
A28: 40125 | B28: 取得借款所收到的现金
A29: 40126 | B29: 收到的其他与筹资活动有关的现金
A30: 40127 | B30: 筹资活动现金流入小计 | C30: =SUM(C27:C29) -> 0
A31: 40128 | B31: 偿还债务所支付的现金
A32: 40129 | B32: 分配股利、利润或偿付利息支付的现金
A33: 40130 | B33: 支付的其他与筹资活动有关的现金
A34: 40131 | B34: 筹资活动现金流出小计 | C34: =SUM(C31:C33) -> 0
A35: 40132 | B35: 筹资活动产生的现金流量净额 | C35: =C30-C34 -> 0
A36: 40133 | B36: 四、汇率变动对现金及现金等价物的影响
A37: 40134 | B37: 五、现金及现金等价物净增加额 | C37: =C12+C25+C35+C36 -> 0
A38: 40135 | B38: 期初现金及现金等价物余额
A39: 40136 | B39: 六、期末现金及现金等价物余额 | C39: =C37+C38 -> 0

Sheet bs2016.12 
A1: 项目编号 | B1: 项目名称（元） | C1: 年初数 | D1: 期末数
A2: 40001 | B2: 货币资金
A3: 40002 | B3: 交易性金融资产
A4: 40003 | B4: 应收票据
A5: 40004 | B5: 应收账款
A6: 40005 | B6: 预付账款
A7: 40006 | B7: 存货
A8: 40007 | B8: 应收利息
A9: 40008 | B9: 应收股利
A10: 40009 | B10: 其他应收款
A11: 40010 | B11: 一年内到期的非流动资产
A12: 40011 | B12: 其他流动资产
A13: 40012 | B13: 流动资产合计 | C13: =SUM(C2:C12) -> 0 | D13: =SUM(D2:D12) -> 0
A14: 40013 | B14: 可供出售金融资产
A15: 40014 | B15: 持有至到期投资
A16: 40015 | B16: 长期应收款
A17: 40016 | B17: 长期股权投资
A18: 40017 | B18: 投资性房地产
A19: 400171 | B19: 固定资产
A20: 400172 | B20: 累计折旧
A21: 400173 | B21: 固定资产减值准备
A22: 40018 | B22: 固定资产净额 | C22: =C19-C20-C21 -> 0 | D22: =D19-D20-D21 -> 0
A23: 40019 | B23: 工程物资
A24: 40020 | B24: 在建工程
A25: 40021 | B25: 固定资产清理
A26: 40022 | B26: 生产性生物资产
A27: 40023 | B27: 油气资产
A28: 40024 | B28: 无形资产
A29: 40025 | B29: 开发支出
A30: 40026 | B30: 商誉
A31: 40027 | B31: 长期待摊费用
A32: 40028 | B32: 递延所得税资产
A33: 40029 | B33: 其他非流动资产
A34: 40030 | B34: 非流动资产合计 | C34: =SUM(C14:C33)-C19-C20-C21 -> 0 | D34: =SUM(D14:D33)-D19-D20-D21 -> 0
A35: 40031 | B35: 资产总计 | C35: =C34+C13 -> 0 | D35: =D34+D13 -> 0
A36: 40032 | B36: 短期借款
A37: 40033 | B37: 交易性金融负债
A38: 40034 | B38: 应付票据
A39: 40035 | B39: 应付账款
A40: 40036 | B40: 预收账款
...

Sheet pl2016.12
A1: 项目编号 | B1: 项目名称（元） | C1: 本月数 | D1: 本年累计
A2: 40064 | B2: 营业收入 | C2: =C3+C4 -> 0 | D2: =D3+D4 -> 0
A3: 400640 | B3: 主营业务收入
A4: 400641 | B4: 其他业务收入
A5: 40065 | B5: 营业成本 | C5: =C6+C7 -> 0 | D5: =D6+D7 -> 0
A6: 400650 | B6: 主营业务成本
A7: 400651 | B7: 其他业务成本
A8: 40066 | B8: 营业税金及附加
A9: 40067 | B9: 销售费用
A10: 40068 | B10: 管理费用
A11: 40069 | B11: 财务费用
A12: 40070 | B12: 资产减值损失
A13: 40071 | B13: 公允价值变动收益
A14: 40072 | B14: 投资收益
A15: 40073 | B15: 营业利润 | C15: =C2-C5-C8-C9-C10-C11-C12+C13+C14 -> 0 | D15: =D2-D5-D8-D9-D10-D11-D12+D13+D14 -> 0
A16: 40074 | B16: 营业外收入
A17: 40075 | B17: 营业外支出
A18: 40076 | B18: 利润总额 | C18: =C15+C16-C17 -> 0 | D18: =D15+D16-D17 -> 0
A19: 40077 | B19: 所得税费用
A20: 40078 | B20: 净利润 | C20: =C18-C19 -> 0 | D20: =D18-D19 -> 0
A21: 40079 | B21: 少数股东权益损益
A22: 40080 | B22: 归属于母公司所有者的净利润 | C22: =C20-C21 -> 0 | D22: =D20-D21 -> 0
A23: 40081 | B23: 每股收益
A24: 40082 | B24: 基本每股收益
A25: 40083 | B25: 稀释每股收益
A26: 40084 | B26: 年初未分配利润
A27: 40085 | B27: 盈余公积补亏
A28: 40086 | B28: 其他转入
A29: 40087 | B29: 可供分配利润
A30: 40088 | B30: 提取法定盈余公积
A31: 40089 | B31: 提取一般风险准备
A32: 40090 | B32: 其他
A33: 40091 | B33: 可供投资者分配的利润 | C33: =C22+C26+C32 -> 0 | D33: =D22+D26+D32 -> 0
A34: 40092 | B34: 应付优先股股利
A35: 40093 | B35: 提取任意盈余公积
A36: 40094 | B36: 应付普通股股利
A37: 40095 | B37: 转作股本的普通股股利
A38: 40096 | B38: 其他
A39: 40097 | B39: 未分配利润 | C39: =C33-C36 -> 0 | D39: =D33-D36-D38 -> 0
A40: 400831 | B40: 其他综合收益
...

Sheet cf2016.12
A1: 项目编号 | B1: 项目名称（元） | C1: 本年累计数
A2: 40098 | B2: 一、经营活动产生的现金流量：
A3: 40100 | B3: 销售商品、提供劳务收到的现金
A4: 40101 | B4: 收到的税费返还
A5: 40102 | B5: 收到其他与经营活动有关的现金
A6: 40103 | B6: 经营活动现金流入小计 | C6: =SUM(C3:C5) -> 0
A7: 40104 | B7: 购买商品、接受劳务支付的现金
A8: 40105 | B8: 支付给职工以及为职工支付的现金
A9: 40106 | B9: 支付的各项税费
A10: 40107 | B10: 支付的其他与经营活动有关的现金
A11: 40108 | B11: 经营活动现金流出小计 | C11: =SUM(C7:C10) -> 0
A12: 40109 | B12: 经营活动产生的现金流量净额 | C12: =C6-C11 -> 0
A13: 40110 | B13: 二、投资活动产生的现金流量：
A14: 40111 | B14: 收回投资所收到的现金
A15: 40112 | B15: 取得投资收益收到的现金
A16: 40113 | B16: 处置固定资产、无形资产和其他长期资产所收回的现金净额
A17: 40114 | B17: 处置子公司及其他营业单位收到的现金净额
A18: 40115 | B18: 收到的其他与投资活动有关的现金
A19: 40116 | B19: 投资活动现金流入小计 | C19: =SUM(C14:C18) -> 0
A20: 40117 | B20: 购建固定资产、无形资产和其他长期资产所支付的现金
A21: 40118 | B21: 投资支付的现金
A22: 40119 | B22: 取得子公司及其他营业单位支付的现金净额
A23: 40120 | B23: 支付其他与投资活动有关的现金
A24: 40121 | B24: 投资活动现金流出小计 | C24: =SUM(C20:C23) -> 0
A25: 40122 | B25: 投资活动产生的现金流量净额 | C25: =C19-C24 -> 0
A26: 40123 | B26: 三、筹资活动产生的现金流量：
A27: 40124 | B27: 吸收投资所收到的现金
A28: 40125 | B28: 取得借款所收到的现金
A29: 40126 | B29: 收到的其他与筹资活动有关的现金
A30: 40127 | B30: 筹资活动现金流入小计 | C30: =SUM(C27:C29) -> 0
A31: 40128 | B31: 偿还债务所支付的现金
A32: 40129 | B32: 分配股利、利润或偿付利息支付的现金
A33: 40130 | B33: 支付的其他与筹资活动有关的现金
A34: 40131 | B34: 筹资活动现金流出小计 | C34: =SUM(C31:C33) -> 0
A35: 40132 | B35: 筹资活动产生的现金流量净额 | C35: =C30-C34 -> 0
A36: 40133 | B36: 四、汇率变动对现金及现金等价物的影响
A37: 40134 | B37: 五、现金及现金等价物净增加额 | C37: =C12+C25+C35+C36 -> 0
A38: 40135 | B38: 期初现金及现金等价物余额
A39: 40136 | B39: 六、期末现金及现金等价物余额 | C39: =C37+C38 -> 0

Sheet bs2015.12
A1: 项目编号 | B1: 项目名称（元） | C1: 年初数 | D1: 期末数
A2: 40001 | B2: 货币资金
A3: 40002 | B3: 交易性金融资产
A4: 40003 | B4: 应收票据
A5: 40004 | B5: 应收账款
A6: 40005 | B6: 预付账款
A7: 40006 | B7: 存货
A8: 40007 | B8: 应收利息
A9: 40008 | B9: 应收股利
A10: 40009 | B10: 其他应收款
A11: 40010 | B11: 一年内到期的非流动资产
A12: 40011 | B12: 其他流动资产
A13: 40012 | B13: 流动资产合计 | C13: =SUM(C2:C12) -> 0 | D13: =SUM(D2:D12) -> 0
A14: 40013 | B14: 可供出售金融资产
A15: 40014 | B15: 持有至到期投资
A16: 40015 | B16: 长期应收款
A17: 40016 | B17: 长期股权投资
A18: 40017 | B18: 投资性房地产
A19: 400171 | B19: 固定资产
A20: 400172 | B20: 累计折旧
A21: 400173 | B21: 固定资产减值准备
A22: 40018 | B22: 固定资产净额 | C22: =C19-C20-C21 -> 0 | D22: =D19-D20-D21 -> 0
A23: 40019 | B23: 工程物资
A24: 40020 | B24: 在建工程
A25: 40021 | B25: 固定资产清理
A26: 40022 | B26: 生产性生物资产
A27: 40023 | B27: 油气资产
A28: 40024 | B28: 无形资产
A29: 40025 | B29: 开发支出
A30: 40026 | B30: 商誉
A31: 40027 | B31: 长期待摊费用
A32: 40028 | B32: 递延所得税资产
A33: 40029 | B33: 其他非流动资产
A34: 40030 | B34: 非流动资产合计 | C34: =SUM(C14:C33)-C19-C20-C21 -> 0 | D34: =SUM(D14:D33)-D19-D20-D21 -> 0
A35: 40031 | B35: 资产总计 | C35: =C34+C13 -> 0 | D35: =D34+D13 -> 0
A36: 40032 | B36: 短期借款
A37: 40033 | B37: 交易性金融负债
A38: 40034 | B38: 应付票据
A39: 40035 | B39: 应付账款
A40: 40036 | B40: 预收账款
...

Sheet pl2015.12
A1: 项目编号 | B1: 项目名称（元） | C1: 本月数
A2: 40064 | B2: 营业收入 | C2: =C3+C4 -> 0 | D2: =D3+D4 -> 0
A3: 400640 | B3: 主营业务收入
A4: 400641 | B4: 其他业务收入
A5: 40065 | B5: 营业成本 | C5: =C6+C7 -> 0 | D5: =D6+D7 -> 0
A6: 400650 | B6: 主营业务成本
A7: 400651 | B7: 其他业务成本
A8: 40066 | B8: 营业税金及附加
A9: 40067 | B9: 销售费用
A10: 40068 | B10: 管理费用
A11: 40069 | B11: 财务费用
A12: 40070 | B12: 资产减值损失
A13: 40071 | B13: 公允价值变动收益
A14: 40072 | B14: 投资收益
A15: 40073 | B15: 营业利润 | C15: =C2-C5-C8-C9-C10-C11-C12+C13+C14 -> 0 | D15: =D2-D5-D8-D9-D10-D11-D12+D13+D14 -> 0
A16: 40074 | B16: 营业外收入
A17: 40075 | B17: 营业外支出
A18: 40076 | B18: 利润总额 | C18: =C15+C16-C17 -> 0 | D18: =D15+D16-D17 -> 0
A19: 40077 | B19: 所得税费用
A20: 40078 | B20: 净利润 | C20: =C18-C19 -> 0 | D20: =D18-D19 -> 0
A21: 40079 | B21: 少数股东权益损益
A22: 40080 | B22: 归属于母公司所有者的净利润 | C22: =C20-C21 -> 0 | D22: =D20-D21 -> 0
A23: 40081 | B23: 每股收益
A24: 40082 | B24: 基本每股收益
A25: 40083 | B25: 稀释每股收益
A26: 40084 | B26: 年初未分配利润
A27: 40085 | B27: 盈余公积补亏
A28: 40086 | B28: 其他转入
A29: 40087 | B29: 可供分配利润
A30: 40088 | B30: 提取法定盈余公积
A31: 40089 | B31: 提取一般风险准备
A32: 40090 | B32: 其他
A33: 40091 | B33: 可供投资者分配的利润 | C33: =C22+C26+C32 -> 0 | D33: =D22+D26+D32 -> 0
A34: 40092 | B34: 应付优先股股利
A35: 40093 | B35: 提取任意盈余公积
A36: 40094 | B36: 应付普通股股利
A37: 40095 | B37: 转作股本的普通股股利
A38: 40096 | B38: 其他
A39: 40097 | B39: 未分配利润 | C39: =C33-C36 -> 0 | D39: =D33-D36-D38 -> 0
A40: 400831 | B40: 其他综合收益
...

Sheet cf2015.12
A1: 项目编号 | B1: 项目名称（元）
A2: 40098 | B2: 一、经营活动产生的现金流量：
A3: 40100 | B3: 销售商品、提供劳务收到的现金
A4: 40101 | B4: 收到的税费返还
A5: 40102 | B5: 收到其他与经营活动有关的现金
A6: 40103 | B6: 经营活动现金流入小计 | C6: =SUM(C3:C5) -> 0
A7: 40104 | B7: 购买商品、接受劳务支付的现金
A8: 40105 | B8: 支付给职工以及为职工支付的现金
A9: 40106 | B9: 支付的各项税费
A10: 40107 | B10: 支付的其他与经营活动有关的现金
A11: 40108 | B11: 经营活动现金流出小计 | C11: =SUM(C7:C10) -> 0
A12: 40109 | B12: 经营活动产生的现金流量净额 | C12: =C6-C11 -> 0
A13: 40110 | B13: 二、投资活动产生的现金流量：
A14: 40111 | B14: 收回投资所收到的现金
A15: 40112 | B15: 取得投资收益收到的现金
A16: 40113 | B16: 处置固定资产、无形资产和其他长期资产所收回的现金净额
A17: 40114 | B17: 处置子公司及其他营业单位收到的现金净额
A18: 40115 | B18: 收到的其他与投资活动有关的现金
A19: 40116 | B19: 投资活动现金流入小计 | C19: =SUM(C14:C18) -> 0
A20: 40117 | B20: 购建固定资产、无形资产和其他长期资产所支付的现金
A21: 40118 | B21: 投资支付的现金
A22: 40119 | B22: 取得子公司及其他营业单位支付的现金净额
A23: 40120 | B23: 支付其他与投资活动有关的现金
A24: 40121 | B24: 投资活动现金流出小计 | C24: =SUM(C20:C23) -> 0
A25: 40122 | B25: 投资活动产生的现金流量净额 | C25: =C19-C24 -> 0
A26: 40123 | B26: 三、筹资活动产生的现金流量：
A27: 40124 | B27: 吸收投资所收到的现金
A28: 40125 | B28: 取得借款所收到的现金
A29: 40126 | B29: 收到的其他与筹资活动有关的现金
A30: 40127 | B30: 筹资活动现金流入小计 | C30: =SUM(C27:C29) -> 0
A31: 40128 | B31: 偿还债务所支付的现金
A32: 40129 | B32: 分配股利、利润或偿付利息支付的现金
A33: 40130 | B33: 支付的其他与筹资活动有关的现金
A34: 40131 | B34: 筹资活动现金流出小计 | C34: =SUM(C31:C33) -> 0
A35: 40132 | B35: 筹资活动产生的现金流量净额 | C35: =C30-C34 -> 0
A36: 40133 | B36: 四、汇率变动对现金及现金等价物的影响
A37: 40134 | B37: 五、现金及现金等价物净增加额 | C37: =C12+C25+C35+C36 -> 0
A38: 40135 | B38: 期初现金及现金等价物余额
A39: 40136 | B39: 六、期末现金及现金等价物余额 | C39: =C37+C38 -> 0

Sheet 财务分析-万位
B1: 43190 | C1: 43100 | D1: 42735 | E1: 42369
A2: 存货净额 | B2: =ROUND('bs2018.03'!D7,0)/IF(LEN($G$6)>4,10000,1) -> 0 | C2: =ROUND('bs2017.12'!D7,0)/IF(LEN($G$6)>4,10000,1) -> 0 | D2: =ROUND('bs2016.12 '!D7,0)/IF(LEN($G$6)>4,10000,1) -> 0 | E2: =ROUND('bs2015.12'!D7,0)/IF(LEN($G$6)>4,10000,1) -> 0
A3: 应收账款净额 | B3: =ROUND('bs2018.03'!D5,0)/IF(LEN($G$6)>4,10000,1) -> 0 | C3: =ROUND('bs2017.12'!D5,0)/IF(LEN($G$6)>4,10000,1) -> 0 | D3: =ROUND('bs2016.12 '!D5,0)/IF(LEN($G$6)>4,10000,1) -> 0 | E3: =ROUND('bs2015.12'!D5,0)/IF(LEN($G$6)>4,10000,1) -> 0
A4: 流动资产 | B4: =ROUND('bs2018.03'!D13,0)/IF(LEN($G$6)>4,10000,1) -> 0 | C4: =ROUND('bs2017.12'!D13,0)/IF(LEN($G$6)>4,10000,1) -> 0 | D4: =ROUND('bs2016.12 '!D13,0)/IF(LEN($G$6)>4,10000,1) -> 0 | E4: =ROUND('bs2015.12'!D13,0)/IF(LEN($G$6)>4,10000,1) -> 0
A5: 固定资产 | B5: =ROUND('bs2018.03'!D22,0)/IF(LEN($G$6)>4,10000,1) -> 0 | C5: =ROUND('bs2017.12'!D22,0)/IF(LEN($G$6)>4,10000,1) -> 0 | D5: =ROUND('bs2016.12 '!D22,0)/IF(LEN($G$6)>4,10000,1) -> 0 | E5: =ROUND('bs2015.12'!D22,0)/IF(LEN($G$6)>4,10000,1) -> 0
A6: 在建工程 | B6: =ROUND('bs2018.03'!D24,0)/IF(LEN($G$6)>4,10000,1) -> 0 | C6: =ROUND('bs2017.12'!D24,0)/IF(LEN($G$6)>4,10000,1) -> 0 | D6: =ROUND('bs2016.12 '!D24,0)/IF(LEN($G$6)>4,10000,1) -> 0 | E6: =ROUND('bs2015.12'!D24,0)/IF(LEN($G$6)>4,10000,1) -> 0 | G6: 单位：万元
A7: 总资产 | B7: =ROUND('bs2018.03'!D35,0)/IF(LEN($G$6)>4,10000,1) -> 0 | C7: =ROUND('bs2017.12'!D35,0)/IF(LEN($G$6)>4,10000,1) -> 0 | D7: =ROUND('bs2016.12 '!D35,0)/IF(LEN($G$6)>4,10000,1) -> 0 | E7: =ROUND('bs2015.12'!D35,0)/IF(LEN($G$6)>4,10000,1) -> 0
A8: 短期借款 | B8: =ROUND('bs2018.03'!D36,0)/IF(LEN($G$6)>4,10000,1) -> 0 | C8: =ROUND('bs2017.12'!D36,0)/IF(LEN($G$6)>4,10000,1) -> 0 | D8: =ROUND('bs2016.12 '!D36,0)/IF(LEN($G$6)>4,10000,1) -> 0 | E8: =ROUND('bs2015.12'!D36,0)/IF(LEN($G$6)>4,10000,1) -> 0
A9: 其他应付款 | B9: =ROUND('bs2018.03'!D45,0)/IF(LEN($G$6)>4,10000,1) -> 0 | C9: =ROUND('bs2017.12'!D45,0)/IF(LEN($G$6)>4,10000,1) -> 0 | D9: =ROUND('bs2016.12 '!D45,0)/IF(LEN($G$6)>4,10000,1) -> 0 | E9: =ROUND('bs2015.12'!D45,0)/IF(LEN($G$6)>4,10000,1) -> 0
A10: 流动负债 | B10: =ROUND('bs2018.03'!D48,0)/IF(LEN($G$6)>4,10000,1) -> 0 | C10: =ROUND('bs2017.12'!D48,0)/IF(LEN($G$6)>4,10000,1) -> 0 | D10: =ROUND('bs2016.12 '!D48,0)/IF(LEN($G$6)>4,10000,1) -> 0 | E10: =ROUND('bs2015.12'!D48,0)/IF(LEN($G$6)>4,10000,1) -> 0
A11: 长期借款 | B11: =ROUND('bs2018.03'!D49,0)/IF(LEN($G$6)>4,10000,1) -> 0 | C11: =ROUND('bs2017.12'!D49,0)/IF(LEN($G$6)>4,10000,1) -> 0 | D11: =ROUND('bs2016.12 '!D49,0)/IF(LEN($G$6)>4,10000,1) -> 0 | E11: =ROUND('bs2015.12'!D49,0)/IF(LEN($G$6)>4,10000,1) -> 0
A12: 长期应付款 | B12: =ROUND('bs2018.03'!D51,0)/IF(LEN($G$6)>4,10000,1) -> 0 | C12: =ROUND('bs2017.12'!D51,0)/IF(LEN($G$6)>4,10000,1) -> 0 | D12: =ROUND('bs2016.12 '!D51,0)/IF(LEN($G$6)>4,10000,1) -> 0 | E12: =ROUND('bs2015.12'!D51,0)/IF(LEN($G$6)>4,10000,1) -> 0
A13: 长期负债 | B13: =ROUND('bs2018.03'!D56,0)/IF(LEN($G$6)>4,10000,1) -> 0 | C13: =ROUND('bs2017.12'!D56,0)/IF(LEN($G$6)>4,10000,1) -> 0 | D13: =ROUND('bs2016.12 '!D56,0)/IF(LEN($G$6)>4,10000,1) -> 0 | E13: =ROUND('bs2015.12'!D56,0)/IF(LEN($G$6)>4,10000,1) -> 0
A14: 总负债 | B14: =ROUND('bs2018.03'!D57,0)/IF(LEN($G$6)>4,10000,1) -> 0 | C14: =ROUND('bs2017.12'!D57,0)/IF(LEN($G$6)>4,10000,1) -> 0 | D14: =ROUND('bs2016.12 '!D57,0)/IF(LEN($G$6)>4,10000,1) -> 0 | E14: =ROUND('bs2015.12'!D57,0)/IF(LEN($G$6)>4,10000,1) -> 0
A15: 股东权益 | B15: =ROUND('bs2018.03'!D67,0)/IF(LEN($G$6)>4,10000,1) -> 0 | C15: =ROUND('bs2017.12'!D67,0)/IF(LEN($G$6)>4,10000,1) -> 0 | D15: =ROUND('bs2016.12 '!D67,0)/IF(LEN($G$6)>4,10000,1) -> 0 | E15: =ROUND('bs2015.12'!D67,0)/IF(LEN($G$6)>4,10000,1) -> 0
A16: 主营业务收入 | B16: =ROUND('pl2018.03'!D2,0)/IF(LEN($G$6)>4,10000,1) -> 0 | C16: =ROUND('pl2017.12'!D2,0)/IF(LEN($G$6)>4,10000,1) -> 0 | D16: =ROUND('pl2016.12'!D2,0)/IF(LEN($G$6)>4,10000,1) -> 0 | E16: =ROUND('pl2015.12'!D2,0)/IF(LEN($G$6)>4,10000,1) -> 0
A17: 主营业务成本 | B17: =ROUND('pl2018.03'!D5,0)/IF(LEN($G$6)>4,10000,1) -> 0 | C17: =ROUND('pl2017.12'!D5,0)/IF(LEN($G$6)>4,10000,1) -> 0 | D17: =ROUND('pl2016.12'!D5,0)/IF(LEN($G$6)>4,10000,1) -> 0 | E17: =ROUND('pl2015.12'!D5,0)/IF(LEN($G$6)>4,10000,1) -> 0
A18: 营业费用 | B18: =ROUND('pl2018.03'!D9,0)/IF(LEN($G$6)>4,10000,1) -> 0 | C18: =ROUND('pl2017.12'!D9,0)/IF(LEN($G$6)>4,10000,1) -> 0 | D18: =ROUND('pl2016.12'!D9,0)/IF(LEN($G$6)>4,10000,1) -> 0 | E18: =ROUND('pl2015.12'!D9,0)/IF(LEN($G$6)>4,10000,1) -> 0
A19: 管理费用 | B19: =ROUND('pl2018.03'!D10,0)/IF(LEN($G$6)>4,10000,1) -> 0 | C19: =ROUND('pl2017.12'!D10,0)/IF(LEN($G$6)>4,10000,1) -> 0 | D19: =ROUND('pl2016.12'!D10,0)/IF(LEN($G$6)>4,10000,1) -> 0 | E19: =ROUND('pl2015.12'!D10,0)/IF(LEN($G$6)>4,10000,1) -> 0
A20: 财务费用 | B20: =ROUND('pl2018.03'!D11,0)/IF(LEN($G$6)>4,10000,1) -> 0 | C20: =ROUND('pl2017.12'!D11,0)/IF(LEN($G$6)>4,10000,1) -> 0 | D20: =ROUND('pl2016.12'!D11,0)/IF(LEN($G$6)>4,10000,1) -> 0 | E20: =ROUND('pl2015.12'!D11,0)/IF(LEN($G$6)>4,10000,1) -> 0
A21: 营业利润 | B21: =ROUND('pl2018.03'!D15,0)/IF(LEN($G$6)>4,10000,1) -> 0 | C21: =ROUND('pl2017.12'!D15,0)/IF(LEN($G$6)>4,10000,1) -> 0 | D21: =ROUND('pl2016.12'!D15,0)/IF(LEN($G$6)>4,10000,1) -> 0 | E21: =ROUND('pl2015.12'!D15,0)/IF(LEN($G$6)>4,10000,1) -> 0
A22: 利润总额 | B22: =ROUND('pl2018.03'!D18,0)/IF(LEN($G$6)>4,10000,1) -> 0 | C22: =ROUND('pl2017.12'!D18,0)/IF(LEN($G$6)>4,10000,1) -> 0 | D22: =ROUND('pl2016.12'!D18,0)/IF(LEN($G$6)>4,10000,1) -> 0 | E22: =ROUND('pl2015.12'!D18,0)/IF(LEN($G$6)>4,10000,1) -> 0
A23: 净利润 | B23: =ROUND('pl2018.03'!D20,0)/IF(LEN($G$6)>4,10000,1) -> 0 | C23: =ROUND('pl2017.12'!D20,0)/IF(LEN($G$6)>4,10000,1) -> 0 | D23: =ROUND('pl2016.12'!D20,0)/IF(LEN($G$6)>4,10000,1) -> 0 | E23: =ROUND('pl2015.12'!D20,0)/IF(LEN($G$6)>4,10000,1) -> 0
A24: 筹资性现金流净流量 | B24: =ROUND('cf2018.03'!C35,0)/IF(LEN($G$6)>4,10000,1) -> 0 | C24: =ROUND('cf2017.12'!C35,0)/IF(LEN($G$6)>4,10000,1) -> 0 | D24: =ROUND('cf2016.12'!C35,0)/IF(LEN($G$6)>4,10000,1) -> 0 | E24: =ROUND('cf2015.12'!C35,0)/IF(LEN($G$6)>4,10000,1) -> 0
A25: 经营性现金流净流量 | B25: =ROUND('cf2018.03'!C12,0)/IF(LEN($G$6)>4,10000,1) -> 0 | C25: =ROUND('cf2017.12'!C12,0)/IF(LEN($G$6)>4,10000,1) -> 0 | D25: =ROUND('cf2016.12'!C12,0)/IF(LEN($G$6)>4,10000,1) -> 0 | E25: =ROUND('cf2015.12'!C12,0)/IF(LEN($G$6)>4,10000,1) -> 0
A26: 偿债能力分析
A27: 流动比率 | B27: =B4/B10 -> #DIV/0! | C27: =C4/C10 -> #DIV/0! | D27: =D4/D10 -> #DIV/0! | E27: =E4/E10 -> #DIV/0!
A28: 速动比率 | B28: =(B4-B2)/B10 -> #DIV/0! | C28: =(C4-C2)/C10 -> #DIV/0! | D28: =(D4-D2)/D10 -> #DIV/0! | E28: =(E4-E2)/E10 -> #DIV/0!
A29: 股东权益比(%) | B29: =B15/B7 -> #DIV/0! | C29: =C15/C7 -> #DIV/0! | D29: =D15/D7 -> #DIV/0! | E29: =E15/E7 -> #DIV/0!
A30: 资产负债率(%) | B30: =B14/B7 -> #DIV/0! | C30: =C14/C7 -> #DIV/0! | D30: =D14/D7 -> #DIV/0! | E30: =E14/E7 -> #DIV/0!
A31: 流动负债率(%) | B31: =B10/B14 -> #DIV/0! | C31: =C10/C14 -> #DIV/0! | D31: =D10/D14 -> #DIV/0! | E31: =E10/E14 -> #DIV/0!
A32: EBITDA利息倍数 | B32: =(B22+B20)/B20 -> #DIV/0! | C32: =(C22+C20)/C20 -> #DIV/0! | D32: =(D22+D20)/D20 -> #DIV/0! | E32: =(E22+E20)/E20 -> #DIV/0!
A33: 经营效率分析
A34: 存货周转率(倍) | B34: =0+(B17/(B2+C2)*2) -> #DIV/0! | C34: =C17/(C2+D2)*2 -> #DIV/0! | D34: =D17/(D2+E2)*2 -> #DIV/0! | E34: =E17/E2 -> #DIV/0!
A35: 总资产周转率(倍) | B35: =0+(B16/(B7+C7)*2) -> #DIV/0! | C35: =C16/(C7+D7)*2 -> #DIV/0! | D35: =D16/(D7+E7)*2 -> #DIV/0! | E35: =E16/E7 -> #DIV/0!
A36: 应收帐款周转率(倍) | B36: =0+(B16/(B3+C3)*2) -> #DIV/0! | C36: =C16/(C3+D3)*2 -> #DIV/0! | D36: =D16/(D3+E3)*2 -> #DIV/0! | E36: =E16/E3 -> #DIV/0!
A37: 主营成本比例(%) | B37: =0+(B17/B16) -> #DIV/0! | C37: =C17/C16 -> #DIV/0! | D37: =D17/D16 -> #DIV/0! | E37: =E17/E16 -> #DIV/0!
A38: 营业费用比例(%) | B38: =0+(B18/B16) -> #DIV/0! | C38: =C18/C16 -> #DIV/0! | D38: =D18/D16 -> #DIV/0! | E38: =E18/E16 -> #DIV/0!
A39: 管理费用比例(%) | B39: =0+(B19/B16) -> #DIV/0! | C39: =C19/C16 -> #DIV/0! | D39: =D19/D16 -> #DIV/0! | E39: =E19/E16 -> #DIV/0!
A40: 财务费用比例(%) | B40: =0+(B20/B16) -> #DIV/0! | C40: =C20/C16 -> #DIV/0! | D40: =D20/D16 -> #DIV/0! | E40: =E20/E16 -> #DIV/0!
...

Sheet 现金流分析表
A1: 项目 | B1: ='财务分析-万位'!B1 -> 43190 | C1: ='财务分析-万位'!C1 -> 43100 | D1: ='财务分析-万位'!D1 -> 42735 | E1: ='财务分析-万位'!E1 -> 42369 | F1: 单位：万元 | G1: =A1 -> 项目 | H1: =B1 -> 43190 | I1: =C1 -> 43100 | J1: =D1 -> 42735 | K1: =E1 -> 42369
A2: 经营活动现金流量净额 | B2: =B3-B4 -> 0 | C2: =C3-C4 -> 0 | D2: =D3-D4 -> 0 | E2: =E3-E4 -> 0 | G2: =A2 -> 经营活动现金流量净额 | H2: =ROUND(B2,0)/IF(LEN($F$1)>4,10000,1) -> 0 | I2: =ROUND(C2,0)/IF(LEN($F$1)>4,10000,1) -> 0 | J2: =ROUND(D2,0)/IF(LEN($F$1)>4,10000,1) -> 0 | K2: =ROUND(E2,0)/IF(LEN($F$1)>4,10000,1) -> 0
A3: 经营活动现金流入 | B3: ='cf2018.03'!C6 -> 0 | C3: ='cf2017.12'!C6 -> 0 | D3: ='cf2016.12'!C6 -> 0 | E3: ='cf2015.12'!C6 -> 0 | G3: =A3 -> 经营活动现金流入 | H3: =ROUND(B3,0)/IF(LEN($F$1)>4,10000,1) -> 0 | I3: =ROUND(C3,0)/IF(LEN($F$1)>4,10000,1) -> 0 | J3: =ROUND(D3,0)/IF(LEN($F$1)>4,10000,1) -> 0 | K3: =ROUND(E3,0)/IF(LEN($F$1)>4,10000,1) -> 0
A4: 经营活动现金流出 | B4: ='cf2018.03'!C11 -> 0 | C4: ='cf2017.12'!C11 -> 0 | D4: ='cf2016.12'!C11 -> 0 | E4: ='cf2015.12'!C11 -> 0 | G4: =A4 -> 经营活动现金流出 | H4: =ROUND(B4,0)/IF(LEN($F$1)>4,10000,1) -> 0 | I4: =ROUND(C4,0)/IF(LEN($F$1)>4,10000,1) -> 0 | J4: =ROUND(D4,0)/IF(LEN($F$1)>4,10000,1) -> 0 | K4: =ROUND(E4,0)/IF(LEN($F$1)>4,10000,1) -> 0
A5: 投资活动现金流量净额 | B5: =B6-B7 -> 0 | C5: =C6-C7 -> 0 | D5: =D6-D7 -> 0 | E5: =E6-E7 -> 0 | G5: =A5 -> 投资活动现金流量净额 | H5: =ROUND(B5,0)/IF(LEN($F$1)>4,10000,1) -> 0 | I5: =ROUND(C5,0)/IF(LEN($F$1)>4,10000,1) -> 0 | J5: =ROUND(D5,0)/IF(LEN($F$1)>4,10000,1) -> 0 | K5: =ROUND(E5,0)/IF(LEN($F$1)>4,10000,1) -> 0
A6: 投资活动现金流入 | B6: ='cf2018.03'!C19 -> 0 | C6: ='cf2017.12'!C19 -> 0 | D6: ='cf2016.12'!C19 -> 0 | E6: ='cf2015.12'!C19 -> 0 | G6: =A6 -> 投资活动现金流入 | H6: =ROUND(B6,0)/IF(LEN($F$1)>4,10000,1) -> 0 | I6: =ROUND(C6,0)/IF(LEN($F$1)>4,10000,1) -> 0 | J6: =ROUND(D6,0)/IF(LEN($F$1)>4,10000,1) -> 0 | K6: =ROUND(E6,0)/IF(LEN($F$1)>4,10000,1) -> 0
A7: 投资活动现金流出 | B7: ='cf2018.03'!C24 -> 0 | C7: ='cf2017.12'!C24 -> 0 | D7: ='cf2016.12'!C24 -> 0 | E7: ='cf2015.12'!C24 -> 0 | G7: =A7 -> 投资活动现金流出 | H7: =ROUND(B7,0)/IF(LEN($F$1)>4,10000,1) -> 0 | I7: =ROUND(C7,0)/IF(LEN($F$1)>4,10000,1) -> 0 | J7: =ROUND(D7,0)/IF(LEN($F$1)>4,10000,1) -> 0 | K7: =ROUND(E7,0)/IF(LEN($F$1)>4,10000,1) -> 0
A8: 筹资活动现金流量净额 | B8: =B9-B10 -> 0 | C8: =C9-C10 -> 0 | D8: =D9-D10 -> 0 | E8: =E9-E10 -> 0 | G8: =A8 -> 筹资活动现金流量净额 | H8: =ROUND(B8,0)/IF(LEN($F$1)>4,10000,1) -> 0 | I8: =ROUND(C8,0)/IF(LEN($F$1)>4,10000,1) -> 0 | J8: =ROUND(D8,0)/IF(LEN($F$1)>4,10000,1) -> 0 | K8: =ROUND(E8,0)/IF(LEN($F$1)>4,10000,1) -> 0
A9: 筹资活动现金流入 | B9: ='cf2018.03'!C30 -> 0 | C9: ='cf2017.12'!C30 -> 0 | D9: ='cf2016.12'!C30 -> 0 | E9: ='cf2015.12'!C30 -> 0 | G9: =A9 -> 筹资活动现金流入 | H9: =ROUND(B9,0)/IF(LEN($F$1)>4,10000,1) -> 0 | I9: =ROUND(C9,0)/IF(LEN($F$1)>4,10000,1) -> 0 | J9: =ROUND(D9,0)/IF(LEN($F$1)>4,10000,1) -> 0 | K9: =ROUND(E9,0)/IF(LEN($F$1)>4,10000,1) -> 0
A10: 筹资活动现金流出 | B10: ='cf2018.03'!C34 -> 0 | C10: ='cf2017.12'!C34 -> 0 | D10: ='cf2016.12'!C34 -> 0 | E10: ='cf2015.12'!C34 -> 0 | G10: =A10 -> 筹资活动现金流出 | H10: =ROUND(B10,0)/IF(LEN($F$1)>4,10000,1) -> 0 | I10: =ROUND(C10,0)/IF(LEN($F$1)>4,10000,1) -> 0 | J10: =ROUND(D10,0)/IF(LEN($F$1)>4,10000,1) -> 0 | K10: =ROUND(E10,0)/IF(LEN($F$1)>4,10000,1) -> 0
A11: 分配股利、利润或偿付利息支付的现金 | B11: ='cf2018.03'!C32 -> 0 | C11: ='cf2017.12'!C32 -> 0 | D11: ='cf2016.12'!C32 -> 0 | E11: ='cf2015.12'!C32 -> 0 | G11: =A11 -> 分配股利、利润或偿付利息支付的现金 | H11: =ROUND(B11,0)/IF(LEN($F$1)>4,10000,1) -> 0 | I11: =ROUND(C11,0)/IF(LEN($F$1)>4,10000,1) -> 0 | J11: =ROUND(D11,0)/IF(LEN($F$1)>4,10000,1) -> 0 | K11: =ROUND(E11,0)/IF(LEN($F$1)>4,10000,1) -> 0

Sheet 财务对比分析表
A1: 项目 | B1: ='财务分析-万位'!B1 -> 43190 | C1: ='财务分析-万位'!C1 -> 43100 | D1: ='财务分析-万位'!D1 -> 42735 | E1: ='财务分析-万位'!E1 -> 42369 | G1: 项目 | H1: =B1 -> 43190 | I1: =C1 -> 43100 | J1: =D1 -> 42735 | K1: =E1 -> 42369
B2: 金额 | C2: 金额 | D2: 金额 | E2: 金额 | H2: 金额 | I2: 金额 | J2: 金额 | K2: 金额
A3: 销售商品收到的现金 | B3: ='cf2018.03'!C3 -> 0 | C3: ='cf2017.12'!C3 -> 0 | D3: ='cf2016.12'!C3 -> 0 | E3: ='cf2015.12'!C3 -> 0 | G3: =A3 -> 销售商品收到的现金 | H3: =ROUND(B3/10000,0) -> 0 | I3: =ROUND(C3/10000,0) -> 0 | J3: =ROUND(D3/10000,0) -> 0 | K3: =ROUND(E3/10000,0) -> 0
A4: 主营业务收入 | B4: ='pl2018.03'!D3 -> 0 | C4: ='pl2017.12'!D3 -> 0 | D4: ='pl2016.12'!D3 -> 0 | E4: ='pl2015.12'!D3 -> 0 | G4: =A4 -> 主营业务收入 | H4: =ROUND(B4/10000,0) -> 0 | I4: =ROUND(C4/10000,0) -> 0 | J4: =ROUND(D4/10000,0) -> 0 | K4: =ROUND(E4/10000,0) -> 0
A5: 购买商品、接受劳务支付的现金 | B5: ='cf2018.03'!C7 -> 0 | C5: ='cf2017.12'!C7 -> 0 | D5: ='cf2016.12'!C7 -> 0 | E5: ='cf2015.12'!C7 -> 0 | G5: =A5 -> 购买商品、接受劳务支付的现金 | H5: =ROUND(B5/10000,0) -> 0 | I5: =ROUND(C5/10000,0) -> 0 | J5: =ROUND(D5/10000,0) -> 0 | K5: =ROUND(E5/10000,0) -> 0
A6: 主营业务成本 | B6: ='pl2018.03'!D6 -> 0 | C6: ='pl2017.12'!D6 -> 0 | D6: ='pl2016.12'!D6 -> 0 | E6: ='pl2015.12'!D6 -> 0 | G6: =A6 -> 主营业务成本 | H6: =ROUND(B6/10000,0) -> 0 | I6: =ROUND(C6/10000,0) -> 0 | J6: =ROUND(D6/10000,0) -> 0 | K6: =ROUND(E6/10000,0) -> 0
A7: 分配股利、利润或偿付利息支付的现金 | B7: ='cf2018.03'!C32 -> 0 | C7: ='cf2017.12'!C32 -> 0 | D7: ='cf2016.12'!C32 -> 0 | E7: ='cf2015.12'!C32 -> 0 | G7: =A7 -> 分配股利、利润或偿付利息支付的现金 | H7: =ROUND(B7/10000,0) -> 0 | I7: =ROUND(C7/10000,0) -> 0 | J7: =ROUND(D7/10000,0) -> 0 | K7: =ROUND(E7/10000,0) -> 0
A8: 财务费用 | B8: ='pl2018.03'!D11 -> 0 | C8: ='pl2017.12'!D11 -> 0 | D8: ='pl2016.12'!D11 -> 0 | E8: ='pl2015.12'!D11 -> 0 | G8: =A8 -> 财务费用 | H8: =ROUND(B8/10000,0) -> 0 | I8: =ROUND(C8/10000,0) -> 0 | J8: =ROUND(D8/10000,0) -> 0 | K8: =ROUND(E8/10000,0) -> 0
A9: 经营性现金净流量 | B9: ='cf2018.03'!C12 -> 0 | C9: ='cf2017.12'!C12 -> 0 | D9: ='cf2016.12'!C12 -> 0 | E9: ='cf2015.12'!C12 -> 0 | G9: =A9 -> 经营性现金净流量 | H9: =ROUND(B9/10000,0) -> 0 | I9: =ROUND(C9/10000,0) -> 0 | J9: =ROUND(D9/10000,0) -> 0 | K9: =ROUND(E9/10000,0) -> 0
A10: 净利润 | B10: ='pl2018.03'!D20 -> 0 | C10: ='pl2017.12'!D20 -> 0 | D10: ='pl2016.12'!D20 -> 0 | E10: ='pl2015.12'!D20 -> 0 | G10: =A10 -> 净利润 | H10: =ROUND(B10/10000,0) -> 0 | I10: =ROUND(C10/10000,0) -> 0 | J10: =ROUND(D10/10000,0) -> 0 | K10: =ROUND(E10/10000,0) -> 0
A11: 盈利现金比 | B11: =B9/B10 -> #DIV/0! | C11: =C9/C10 -> #DIV/0! | D11: =D9/D10 -> #DIV/0! | E11: =E9/E10 -> #DIV/0! | G11: =A11 -> 盈利现金比 | H11: =B11 -> #DIV/0! | I11: =C11 -> #DIV/0! | J11: =D11 -> #DIV/0! | K11: =E11 -> #DIV/0!

Sheet 财务变化表
F2: ='财务分析-万位'!G6 -> 单位：万元
B3: 科目 | C3: ='财务分析-万位'!B1 -> 43190 | D3: ='财务分析-万位'!C1 -> 43100 | E3: ='财务分析-万位'!D1 -> 42735 | F3: ='财务分析-万位'!E1 -> 42369
B4: 总资产 | C4: ='财务分析-万位'!B7 -> 0 | D4: ='财务分析-万位'!C7 -> 0 | E4: ='财务分析-万位'!D7 -> 0 | F4: ='财务分析-万位'!E7 -> 0
B5: 净资产 | C5: ='财务分析-万位'!B15 -> 0 | D5: ='财务分析-万位'!C15 -> 0 | E5: ='财务分析-万位'!D15 -> 0 | F5: ='财务分析-万位'!E15 -> 0
B6: 资产负债率 | C6: ='财务分析-万位'!B30 -> #DIV/0! | D6: ='财务分析-万位'!C30 -> #DIV/0! | E6: ='财务分析-万位'!D30 -> #DIV/0! | F6: ='财务分析-万位'!E30 -> #DIV/0!
B7: 营业收入 | C7: ='财务分析-万位'!B16 -> 0 | D7: ='财务分析-万位'!C16 -> 0 | E7: ='财务分析-万位'!D16 -> 0 | F7: ='财务分析-万位'!E16 -> 0
B8: 利润总额 | C8: ='财务分析-万位'!B22 -> 0 | D8: ='财务分析-万位'!C22 -> 0 | E8: ='财务分析-万位'!D22 -> 0 | F8: ='财务分析-万位'!E22 -> 0
B9: 经营性现金净流量 | C9: ='财务分析-万位'!B25 -> 0 | D9: ='财务分析-万位'!C25 -> 0 | E9: ='财务分析-万位'!D25 -> 0 | F9: ='财务分析-万位'!E25 -> 0
B10: 筹资性现金净流量 | C10: ='财务分析-万位'!B24 -> 0 | D10: ='财务分析-万位'!C24 -> 0 | E10: ='财务分析-万位'!D24 -> 0 | F10: ='财务分析-万位'!E24 -> 0

Sheet 资产负债权益结构分析
J1: 单位：万元
B2: 项目 | C2: ='财务分析-万位'!B1 -> 43190 | E2: ='财务分析-万位'!C1 -> 43100 | G2: ='财务分析-万位'!D1 -> 42735 | I2: ='财务分析-万位'!E1 -> 42369
C3: 金额 | D3: 占比 | E3: 金额 | F3: 占比 | G3: 金额 | H3: 占比 | I3: 金额 | J3: 占比
B4: 货币资金 | C4: =ROUND('bs2018.03'!D2,0)/IF(LEN($J$1)>4,10000,1) -> 0 | D4: =C4/$C$37 -> #DIV/0! | E4: =ROUND('bs2017.12'!D2,0)/IF(LEN($J$1)>4,10000,1) -> 0 | F4: =E4/$E$37 -> #DIV/0! | G4: =ROUND('bs2016.12 '!D2,0)/IF(LEN($J$1)>4,10000,1) -> 0 | H4: =G4/$G$37 -> #DIV/0! | I4: =ROUND('bs2015.12'!D2,0)/IF(LEN($J$1)>4,10000,1) -> 0 | J4: =I4/$I$37 -> #DIV/0!
B5: 交易性金融资产 | C5: =ROUND('bs2018.03'!D3,0)/IF(LEN($J$1)>4,10000,1) -> 0 | D5: =C5/$C$37 -> #DIV/0! | E5: =ROUND('bs2017.12'!D3,0)/IF(LEN($J$1)>4,10000,1) -> 0 | F5: =E5/$E$37 -> #DIV/0! | G5: =ROUND('bs2016.12 '!D3,0)/IF(LEN($J$1)>4,10000,1) -> 0 | H5: =G5/$G$37 -> #DIV/0! | I5: =ROUND('bs2015.12'!D3,0)/IF(LEN($J$1)>4,10000,1) -> 0 | J5: =I5/$I$37 -> #DIV/0!
B6: 应收票据 | C6: =ROUND('bs2018.03'!D4,0)/IF(LEN($J$1)>4,10000,1) -> 0 | D6: =C6/$C$37 -> #DIV/0! | E6: =ROUND('bs2017.12'!D4,0)/IF(LEN($J$1)>4,10000,1) -> 0 | F6: =E6/$E$37 -> #DIV/0! | G6: =ROUND('bs2016.12 '!D4,0)/IF(LEN($J$1)>4,10000,1) -> 0 | H6: =G6/$G$37 -> #DIV/0! | I6: =ROUND('bs2015.12'!D4,0)/IF(LEN($J$1)>4,10000,1) -> 0 | J6: =I6/$I$37 -> #DIV/0!
B7: 应收账款 | C7: =ROUND('bs2018.03'!D5,0)/IF(LEN($J$1)>4,10000,1) -> 0 | D7: =C7/$C$37 -> #DIV/0! | E7: =ROUND('bs2017.12'!D5,0)/IF(LEN($J$1)>4,10000,1) -> 0 | F7: =E7/$E$37 -> #DIV/0! | G7: =ROUND('bs2016.12 '!D5,0)/IF(LEN($J$1)>4,10000,1) -> 0 | H7: =G7/$G$37 -> #DIV/0! | I7: =ROUND('bs2015.12'!D5,0)/IF(LEN($J$1)>4,10000,1) -> 0 | J7: =I7/$I$37 -> #DIV/0!
B8: 预付账款 | C8: =ROUND('bs2018.03'!D6,0)/IF(LEN($J$1)>4,10000,1) -> 0 | D8: =C8/$C$37 -> #DIV/0! | E8: =ROUND('bs2017.12'!D6,0)/IF(LEN($J$1)>4,10000,1) -> 0 | F8: =E8/$E$37 -> #DIV/0! | G8: =ROUND('bs2016.12 '!D6,0)/IF(LEN($J$1)>4,10000,1) -> 0 | H8: =G8/$G$37 -> #DIV/0! | I8: =ROUND('bs2015.12'!D6,0)/IF(LEN($J$1)>4,10000,1) -> 0 | J8: =I8/$I$37 -> #DIV/0!
B9: 存货 | C9: =ROUND('bs2018.03'!D7,0)/IF(LEN($J$1)>4,10000,1) -> 0 | D9: =C9/$C$37 -> #DIV/0! | E9: =ROUND('bs2017.12'!D7,0)/IF(LEN($J$1)>4,10000,1) -> 0 | F9: =E9/$E$37 -> #DIV/0! | G9: =ROUND('bs2016.12 '!D7,0)/IF(LEN($J$1)>4,10000,1) -> 0 | H9: =G9/$G$37 -> #DIV/0! | I9: =ROUND('bs2015.12'!D7,0)/IF(LEN($J$1)>4,10000,1) -> 0 | J9: =I9/$I$37 -> #DIV/0!
B10: 应收利息 | C10: =ROUND('bs2018.03'!D8,0)/IF(LEN($J$1)>4,10000,1) -> 0 | D10: =C10/$C$37 -> #DIV/0! | E10: =ROUND('bs2017.12'!D8,0)/IF(LEN($J$1)>4,10000,1) -> 0 | F10: =E10/$E$37 -> #DIV/0! | G10: =ROUND('bs2016.12 '!D8,0)/IF(LEN($J$1)>4,10000,1) -> 0 | H10: =G10/$G$37 -> #DIV/0! | I10: =ROUND('bs2015.12'!D8,0)/IF(LEN($J$1)>4,10000,1) -> 0 | J10: =I10/$I$37 -> #DIV/0!
B11: 应收股利 | C11: =ROUND('bs2018.03'!D9,0)/IF(LEN($J$1)>4,10000,1) -> 0 | D11: =C11/$C$37 -> #DIV/0! | E11: =ROUND('bs2017.12'!D9,0)/IF(LEN($J$1)>4,10000,1) -> 0 | F11: =E11/$E$37 -> #DIV/0! | G11: =ROUND('bs2016.12 '!D9,0)/IF(LEN($J$1)>4,10000,1) -> 0 | H11: =G11/$G$37 -> #DIV/0! | I11: =ROUND('bs2015.12'!D9,0)/IF(LEN($J$1)>4,10000,1) -> 0 | J11: =I11/$I$37 -> #DIV/0!
B12: 其他应收款 | C12: =ROUND('bs2018.03'!D10,0)/IF(LEN($J$1)>4,10000,1) -> 0 | D12: =C12/$C$37 -> #DIV/0! | E12: =ROUND('bs2017.12'!D10,0)/IF(LEN($J$1)>4,10000,1) -> 0 | F12: =E12/$E$37 -> #DIV/0! | G12: =ROUND('bs2016.12 '!D10,0)/IF(LEN($J$1)>4,10000,1) -> 0 | H12: =G12/$G$37 -> #DIV/0! | I12: =ROUND('bs2015.12'!D10,0)/IF(LEN($J$1)>4,10000,1) -> 0 | J12: =I12/$I$37 -> #DIV/0!
B13: 一年内到期的非流动资产 | C13: =ROUND('bs2018.03'!D11,0)/IF(LEN($J$1)>4,10000,1) -> 0 | D13: =C13/$C$37 -> #DIV/0! | E13: =ROUND('bs2017.12'!D11,0)/IF(LEN($J$1)>4,10000,1) -> 0 | F13: =E13/$E$37 -> #DIV/0! | G13: =ROUND('bs2016.12 '!D11,0)/IF(LEN($J$1)>4,10000,1) -> 0 | H13: =G13/$G$37 -> #DIV/0! | I13: =ROUND('bs2015.12'!D11,0)/IF(LEN($J$1)>4,10000,1) -> 0 | J13: =I13/$I$37 -> #DIV/0!
B14: 其他流动资产 | C14: =ROUND('bs2018.03'!D12,0)/IF(LEN($J$1)>4,10000,1) -> 0 | D14: =C14/$C$37 -> #DIV/0! | E14: =ROUND('bs2017.12'!D12,0)/IF(LEN($J$1)>4,10000,1) -> 0 | F14: =E14/$E$37 -> #DIV/0! | G14: =ROUND('bs2016.12 '!D12,0)/IF(LEN($J$1)>4,10000,1) -> 0 | H14: =G14/$G$37 -> #DIV/0! | I14: =ROUND('bs2015.12'!D12,0)/IF(LEN($J$1)>4,10000,1) -> 0 | J14: =I14/$I$37 -> #DIV/0!
B15: 流动资产合计 | C15: =ROUND('bs2018.03'!D13,0)/IF(LEN($J$1)>4,10000,1) -> 0 | D15: =C15/$C$37 -> #DIV/0! | E15: =ROUND('bs2017.12'!D13,0)/IF(LEN($J$1)>4,10000,1) -> 0 | F15: =E15/$E$37 -> #DIV/0! | G15: =ROUND('bs2016.12 '!D13,0)/IF(LEN($J$1)>4,10000,1) -> 0 | H15: =G15/$G$37 -> #DIV/0! | I15: =ROUND('bs2015.12'!D13,0)/IF(LEN($J$1)>4,10000,1) -> 0 | J15: =I15/$I$37 -> #DIV/0!
... B37: 资产总计 | C37: =ROUND('bs2018.03'!D35,0)/IF(LEN($J$1)>4,10000,1) -> 0 | D37: =C37/$C$37 -> #DIV/0! | E37: =ROUND('bs2017.12'!D35,0)/IF(LEN($J$1)>4,10000,1) -> 0 | F37: =E37/$E$37 -> #DIV/0! | G37: =ROUND('bs2016.12 '!D35,0)/IF(LEN($J$1)>4,10000,1) -> 0 | H37: =G37/$G$37 -> #DIV/0! | I37: =ROUND('bs2015.12'!D35,0)/IF(LEN($J$1)>4,10000,1) -> 0 | J37: =I37/$I$37 -> #DIV/0!
B39: 项目 | C39: ='财务分析-万位'!B1 -> 43190 | E39: ='财务分析-万位'!C1 -> 43100 | G39: ='财务分析-万位'!D1 -> 42735 | I39: ='财务分析-万位'!E1 -> 42369
C40: 金额 | D40: 占比 | E40: 金额 | F40: 占比 | G40: 金额 | H40: 占比 | I40: 金额 | J40: 占比
B41: 短期借款 | C41: =ROUND('bs2018.03'!D36,0)/IF(LEN($J$1)>4,10000,1) -> 0 | D41: =C41/$C$62 -> #DIV/0! | E41: =ROUND('bs2017.12'!D36,0)/IF(LEN($J$1)>4,10000,1) -> 0 | F41: =E41/$E$62 -> #DIV/0! | G41: =ROUND('bs2016.12 '!D36,0)/IF(LEN($J$1)>4,10000,1) -> 0 | H41: =G41/$G$62 -> #DIV/0! | I41: =ROUND('bs2015.12'!D36,0)/IF(LEN($J$1)>4,10000,1) -> 0 | J41: =I41/$I$62 -> #DIV/0!
B42: 交易性金融负债 | C42: =ROUND('bs2018.03'!D37,0)/IF(LEN($J$1)>4,10000,1) -> 0 | D42: =C42/$C$62 -> #DIV/0! | E42: =ROUND('bs2017.12'!D37,0)/IF(LEN($J$1)>4,10000,1) -> 0 | F42: =E42/$E$62 -> #DIV/0! | G42: =ROUND('bs2016.12 '!D37,0)/IF(LEN($J$1)>4,10000,1) -> 0 | H42: =G42/$G$62 -> #DIV/0! | I42: =ROUND('bs2015.12'!D37,0)/IF(LEN($J$1)>4,10000,1) -> 0 | J42: =I42/$I$62 -> #DIV/0!
B43: 应付票据 | C43: =ROUND('bs2018.03'!D38,0)/IF(LEN($J$1)>4,10000,1) -> 0 | D43: =C43/$C$62 -> #DIV/0! | E43: =ROUND('bs2017.12'!D38,0)/IF(LEN($J$1)>4,10000,1) -> 0 | F43: =E43/$E$62 -> #DIV/0! | G43: =ROUND('bs2016.12 '!D38,0)/IF(LEN($J$1)>4,10000,1) -> 0 | H43: =G43/$G$62 -> #DIV/0! | I43: =ROUND('bs2015.12'!D38,0)/IF(LEN($J$1)>4,10000,1) -> 0 | J43: =I43/$I$62 -> #DIV/0!
B44: 应付账款 | C44: =ROUND('bs2018.03'!D39,0)/IF(LEN($J$1)>4,10000,1) -> 0 | D44: =C44/$C$62 -> #DIV/0! | E44: =ROUND('bs2017.12'!D39,0)/IF(LEN($J$1)>4,10000,1) -> 0 | F44: =E44/$E$62 -> #DIV/0! | G44: =ROUND('bs2016.12 '!D39,0)/IF(LEN($J$1)>4,10000,1) -> 0 | H44: =G44/$G$62 -> #DIV/0! | I44: =ROUND('bs2015.12'!D39,0)/IF(LEN($J$1)>4,10000,1) -> 0 | J44: =I44/$I$62 -> #DIV/0!
B45: 预收账款 | C45: =ROUND('bs2018.03'!D40,0)/IF(LEN($J$1)>4,10000,1) -> 0 | D45: =C45/$C$62 -> #DIV/0! | E45: =ROUND('bs2017.12'!D40,0)/IF(LEN($J$1)>4,10000,1) -> 0 | F45: =E45/$E$62 -> #DIV/0! | G45: =ROUND('bs2016.12 '!D40,0)/IF(LEN($J$1)>4,10000,1) -> 0 | H45: =G45/$G$62 -> #DIV/0! | I45: =ROUND('bs2015.12'!D40,0)/IF(LEN($J$1)>4,10000,1) -> 0 | J45: =I45/$I$62 -> #DIV/0!
B46: 应付职工薪酬 | C46: =ROUND('bs2018.03'!D41,0)/IF(LEN($J$1)>4,10000,1) -> 0 | D46: =C46/$C$62 -> #DIV/0! | E46: =ROUND('bs2017.12'!D41,0)/IF(LEN($J$1)>4,10000,1) -> 0 | F46: =E46/$E$62 -> #DIV/0! | G46: =ROUND('bs2016.12 '!D41,0)/IF(LEN($J$1)>4,10000,1) -> 0 | H46: =G46/$G$62 -> #DIV/0! | I46: =ROUND('bs2015.12'!D41,0)/IF(LEN($J$1)>4,10000,1) -> 0 | J46: =I46/$I$62 -> #DIV/0!
B47: 应交税费 | C47: =ROUND('bs2018.03'!D42,0)/IF(LEN($J$1)>4,10000,1) -> 0 | D47: =C47/$C$62 -> #DIV/0! | E47: =ROUND('bs2017.12'!D42,0)/IF(LEN($J$1)>4,10000,1) -> 0 | F47: =E47/$E$62 -> #DIV/0! | G47: =ROUND('bs2016.12 '!D42,0)/IF(LEN($J$1)>4,10000,1) -> 0 | H47: =G47/$G$62 -> #DIV/0! | I47: =ROUND('bs2015.12'!D42,0)/IF(LEN($J$1)>4,10000,1) -> 0 | J47: =I47/$I$62 -> #DIV/0!
B48: 应付利息 | C48: =ROUND('bs2018.03'!D43,0)/IF(LEN($J$1)>4,10000,1) -> 0 | D48: =C48/$C$62 -> #DIV/0! | E48: =ROUND('bs2017.12'!D43,0)/IF(LEN($J$1)>4,10000,1) -> 0 | F48: =E48/$E$62 -> #DIV/0! | G48: =ROUND('bs2016.12 '!D43,0)/IF(LEN($J$1)>4,10000,1) -> 0 | H48: =G48/$G$62 -> #DIV/0! | I48: =ROUND('bs2015.12'!D43,0)/IF(LEN($J$1)>4,10000,1) -> 0 | J48: =I48/$I$62 -> #DIV/0!
B49: 应付股利 | C49: =ROUND('bs2018.03'!D44,0)/IF(LEN($J$1)>4,10000,1) -> 0 | D49: =C49/$C$62 -> #DIV/0! | E49: =ROUND('bs2017.12'!D44,0)/IF(LEN($J$1)>4,10000,1) -> 0 | F49: =E49/$E$62 -> #DIV/0! | G49: =ROUND('bs2016.12 '!D44,0)/IF(LEN($J$1)>4,10000,1) -> 0 | H49: =G49/$G$62 -> #DIV/0! | I49: =ROUND('bs2015.12'!D44,0)/IF(LEN($J$1)>4,10000,1) -> 0 | J49: =I49/$I$62 -> #DIV/0!
B50: 其他应付款 | C50: =ROUND('bs2018.03'!D45,0)/IF(LEN($J$1)>4,10000,1) -> 0 | D50: =C50/$C$62 -> #DIV/0! | E50: =ROUND('bs2017.12'!D45,0)/IF(LEN($J$1)>4,10000,1) -> 0 | F50: =E50/$E$62 -> #DIV/0! | G50: =ROUND('bs2016.12 '!D45,0)/IF(LEN($J$1)>4,10000,1) -> 0 | H50: =G50/$G$62 -> #DIV/0! | I50: =ROUND('bs2015.12'!D45,0)/IF(LEN($J$1)>4,10000,1) -> 0 | J50: =I50/$I$62 -> #DIV/0!
B51: 一年内到期的非流动负债 | C51: =ROUND('bs2018.03'!D46,0)/IF(LEN($J$1)>4,10000,1) -> 0 | D51: =C51/$C$62 -> #DIV/0! | E51: =ROUND('bs2017.12'!D46,0)/IF(LEN($J$1)>4,10000,1) -> 0 | F51: =E51/$E$62 -> #DIV/0! | G51: =ROUND('bs2016.12 '!D46,0)/IF(LEN($J$1)>4,10000,1) -> 0 | H51: =G51/$G$62 -> #DIV/0! | I51: =ROUND('bs2015.12'!D46,0)/IF(LEN($J$1)>4,10000,1) -> 0 | J51: =I51/$I$62 -> #DIV/0!
B52: 其他流动负债 | C52: =ROUND('bs2018.03'!D47,0)/IF(LEN($J$1)>4,10000,1) -> 0 | D52: =C52/$C$62 -> #DIV/0! | E52: =ROUND('bs2017.12'!D47,0)/IF(LEN($J$1)>4,10000,1) -> 0 | F52: =E52/$E$62 -> #DIV/0! | G52: =ROUND('bs2016.12 '!D47,0)/IF(LEN($J$1)>4,10000,1) -> 0 | H52: =G52/$G$62 -> #DIV/0! | I52: =ROUND('bs2015.12'!D47,0)/IF(LEN($J$1)>4,10000,1) -> 0 | J52: =I52/$I$62 -> #DIV/0!
... B62: 负债合计 | C62: =ROUND('bs2018.03'!D57,0)/IF(LEN($J$1)>4,10000,1) -> 0 | D62: =C62/$C$62 -> #DIV/0! | E62: =ROUND('bs2017.12'!D57,0)/IF(LEN($J$1)>4,10000,1) -> 0 | F62: =E62/$E$62 -> #DIV/0! | G62: =ROUND('bs2016.12 '!D57,0)/IF(LEN($J$1)>4,10000,1) -> 0 | H62: =G62/$G$62 -> #DIV/0! | I62: =ROUND('bs2015.12'!D57,0)/IF(LEN($J$1)>4,10000,1) -> 0 | J62: =I62/$I$62 -> #DIV/0!
B64: 项目 | C64: ='财务分析-万位'!B1 -> 43190 | E64: ='财务分析-万位'!C1 -> 43100 | G64: ='财务分析-万位'!D1 -> 42735 | I64: ='财务分析-万位'!E1 -> 42369
C65: 金额 | D65: 占比 | E65: 金额 | F65: 占比 | G65: 金额 | H65: 占比 | I65: 金额 | J65: 占比
B66: 实收资本（或股本） | C66: =ROUND('bs2018.03'!D58,0)/IF(LEN($J$1)>4,10000,1) -> 0 | D66: =C66/$C$75 -> #DIV/0! | E66: =ROUND('bs2017.12'!D58,0)/IF(LEN($J$1)>4,10000,1) -> 0 | F66: =E66/$E$75 -> #DIV/0! | G66: =ROUND('bs2016.12 '!D58,0)/IF(LEN($J$1)>4,10000,1) -> 0 | H66: =G66/$G$75 -> #DIV/0! | I66: =ROUND('bs2015.12'!D58,0)/IF(LEN($J$1)>4,10000,1) -> 0 | J66: =I66/$I$75 -> #DIV/0!
B67: 资本公积 | C67: =ROUND('bs2018.03'!D59,0)/IF(LEN($J$1)>4,10000,1) -> 0 | D67: =C67/$C$75 -> #DIV/0! | E67: =ROUND('bs2017.12'!D59,0)/IF(LEN($J$1)>4,10000,1) -> 0 | F67: =E67/$E$75 -> #DIV/0! | G67: =ROUND('bs2016.12 '!D59,0)/IF(LEN($J$1)>4,10000,1) -> 0 | H67: =G67/$G$75 -> #DIV/0! | I67: =ROUND('bs2015.12'!D59,0)/IF(LEN($J$1)>4,10000,1) -> 0 | J67: =I67/$I$75 -> #DIV/0!
B68: 库存股 | C68: =ROUND('bs2018.03'!D60,0)/IF(LEN($J$1)>4,10000,1) -> 0 | D68: =C68/$C$75 -> #DIV/0! | E68: =ROUND('bs2017.12'!D60,0)/IF(LEN($J$1)>4,10000,1) -> 0 | F68: =E68/$E$75 -> #DIV/0! | G68: =ROUND('bs2016.12 '!D60,0)/IF(LEN($J$1)>4,10000,1) -> 0 | H68: =G68/$G$75 -> #DIV/0! | I68: =ROUND('bs2015.12'!D60,0)/IF(LEN($J$1)>4,10000,1) -> 0 | J68: =I68/$I$75 -> #DIV/0!
B69: 专项储备 | C69: =ROUND('bs2018.03'!D61,0)/IF(LEN($J$1)>4,10000,1) -> 0 | D69: =C69/$C$75 -> #DIV/0! | E69: =ROUND('bs2017.12'!D61,0)/IF(LEN($J$1)>4,10000,1) -> 0 | F69: =E69/$E$75 -> #DIV/0! | G69: =ROUND('bs2016.12 '!D61,0)/IF(LEN($J$1)>4,10000,1) -> 0 | H69: =G69/$G$75 -> #DIV/0! | I69: =ROUND('bs2015.12'!D61,0)/IF(LEN($J$1)>4,10000,1) -> 0 | J69: =I69/$I$75 -> #DIV/0!
B70: 盈余公积 | C70: =ROUND('bs2018.03'!D62,0)/IF(LEN($J$1)>4,10000,1) -> 0 | D70: =C70/$C$75 -> #DIV/0! | E70: =ROUND('bs2017.12'!D62,0)/IF(LEN($J$1)>4,10000,1) -> 0 | F70: =E70/$E$75 -> #DIV/0! | G70: =ROUND('bs2016.12 '!D62,0)/IF(LEN($J$1)>4,10000,1) -> 0 | H70: =G70/$G$75 -> #DIV/0! | I70: =ROUND('bs2015.12'!D62,0)/IF(LEN($J$1)>4,10000,1) -> 0 | J70: =I70/$I$75 -> #DIV/0!
B71: 未分配利润 | C71: =ROUND('bs2018.03'!D63,0)/IF(LEN($J$1)>4,10000,1) -> 0 | D71: =C71/$C$75 -> #DIV/0! | E71: =ROUND('bs2017.12'!D63,0)/IF(LEN($J$1)>4,10000,1) -> 0 | F71: =E71/$E$75 -> #DIV/0! | G71: =ROUND('bs2016.12 '!D63,0)/IF(LEN($J$1)>4,10000,1) -> 0 | H71: =G71/$G$75 -> #DIV/0! | I71: =ROUND('bs2015.12'!D63,0)/IF(LEN($J$1)>4,10000,1) -> 0 | J71: =I71/$I$75 -> #DIV/0!
B72: 外币报表折算差额 | C72: =ROUND('bs2018.03'!D64,0)/IF(LEN($J$1)>4,10000,1) -> 0 | D72: =C72/$C$75 -> #DIV/0! | E72: =ROUND('bs2017.12'!D64,0)/IF(LEN($J$1)>4,10000,1) -> 0 | F72: =E72/$E$75 -> #DIV/0! | G72: =ROUND('bs2016.12 '!D64,0)/IF(LEN($J$1)>4,10000,1) -> 0 | H72: =G72/$G$75 -> #DIV/0! | I72: =ROUND('bs2015.12'!D64,0)/IF(LEN($J$1)>4,10000,1) -> 0 | J72: =I72/$I$75 -> #DIV/0!
...
